***结构不佳的代码不能运行。发现错误的最好时间是编译期，其次在运行期***

------

# 一、概念

- 错误恢复机制是每种程序的基本要素，保证每个组件都足够强壮
- 异常处理是java中唯一正式的错误报告机制，并且通过编译器强制执行

## 1. 基本知识

- 优点一： 问题出现了，不应该置之不理，如果不能解决，那么继续让上层帮你解决
- 优点二： 降低处理代码的复杂度。这样就不用在任何调用包含该异常的方法时候去显示处理

### 1.1 异常步骤

- 使用new在堆上创建异常对象，然后当前的执行路径被终止，并且从当前环境中弹出异常对象的引用
- 异常处理机制接管程序，并开始寻找一个恰当的地方来继续执行程序，即异常处理程序
- 异常处理程序是将程序从错误状态中恢复，使得程序要么换一种方式运行(抛出由调用方处理)，要么继续运行下去(不抛出，直接处理)

  a. 异常可以被看作是一种恢复机制， 如果程序什么地方出现了问题，不允许程序继续往下走，而是恢复到某一个稳定的点上。

### 1.2 异常参数

- 标准异常： 一般包含默认构造器和接受字符串作为参数的构造器
- throw new NullPointerException("error message"):            将异常对象的引用抛出，类似于一个方法的返回值，用来结束当前方法
- 能够抛出任意类型的Throwable对象，错误信息可以通过异常对象内部或异常类名称来暗示

### 1.3 捕获异常

- 监控区域：  使用try  catch来捕获
- 终止类型： 一旦异常发生，表明错误已经无法挽回，也不能回来继续执行
- 恢复模型（用的很少）： 是修正错误，认可第二次能成功。 在chatch模块中调用方法来修正该错误， 将try在for中循环

### 1.4 自定义异常

- 优先使用java体系中自带的异常
- 自定义异常时，必须从已有的异常中继承，且选择意思相近的来继承
- 异常尽可能做到见名知意，很多异常的继承关系，也是为了方便用户知道这种异常大概是什么类型的异常

```java
package com.nike.exception;

public class Demo01 {
    public static void main(String[] args) {
        BusinessException businessException = new BusinessException("贷款异常");
        System.out.println(businessException.getMessage());
    }
}

class BusinessException extends RuntimeException{

    String time;

    /**1. 默认无参构造器*/
    BusinessException(){
        super();
    }

    /**2. 带errorMessage的参构造器，显示调用父类构造器*/
    BusinessException(String message){
        super(message);
    }

    /**3. 更进一步自定义构造器*/
    BusinessException(String message, String time){
        super(message);
        this.time = time;
    }

    /**4. 可以对根类Throwable中的方法进行覆盖，从而提供一些自定义的信息*/
    @Override
    public String getMessage(){
        return "接受消息" + time;
    }
}
```

## 2. 异常说明

- 针对 Checked Exception，除了RuntimeException之外的所有异常
- 最佳实践： 如果在一个方法中可能抛出Checked Exception， 那么就在方法声明处 **多加** 一个异常声明，从而迫使客户端在调用这个方法的时候，强制他去处理该可能的异常
- 编译器相信这个声明，就会迫使调用方，要么处理这个异常，要么就继续向上抛出
- 这种在编译时候被强制检查的就叫做 Checked Exception

```java
class Excel {

    public static void main(String[] args) throws Exception {
        Excel excel = new Excel();
        excel.peopleEat();
    }

    public void peopleEat() throws Exception {
        eat();
    }

    public void eat() throws Exception {
        try {
            int i = 1 / 0;
        } catch (Exception e) {
            throw new Exception("zero mistake");
        }
    }
}
```

## 3. 异常捕获

### 3.1 常见methods

```java
package com.nike.exception;

public class Demo01 {
    public static void main(String[] args) {
        getInfo();

    }

    public static void getInfo() {
        try {
            int a = 1 / 0;
        } catch (Exception e) {
            /**1. 继承自基类Throwable的方法：
             *    e.getMessage()：             / by zero
             *    e.getLocalizedMessage()：    / by zero
             *    e.toString()：               java.lang.ArithmeticException: / by zero*/
            System.out.println("e.getMessage: " + e.getMessage());
            System.out.println("e.getLocalizedMessage：" + e.getLocalizedMessage());
            System.out.println("e.toString: " + e.toString());

            /**2. e.printStackTrace():  打印异常及异常调用栈轨迹
             *                         2.1 不管在什么catch中是什么代码顺序，都会放在最后面执行
             *                        
             *  java.lang.ArithmeticException: / by zero
             * 	at com.nike.exception.Demo01.getInfo(Demo01.java:12)
             * 	at com.nike.exception.Demo01.main(Demo01.java:5)
             *
             *  */
            System.out.println("hehe");
            e.printStackTrace();
            System.out.println("haha");

            /**3. 调用Object的方法打印类名  e.getClass().getSimpleName()：  ArithmeticException*/
            System.out.println(e.getClass().getSimpleName());


            /**4. 打印具体的栈轨迹：e.getStackTrace()： 每个元素都是栈中的一帧
             *
             * com.nike.exception.Demo01.getInfo(Demo01.java:12)
             * com.nike.exception.Demo01.main(Demo01.java:5)
             * */
            StackTraceElement[] stackTrace = e.getStackTrace();
            for (StackTraceElement element : stackTrace) {
                System.out.println(element);
            }
        }

    }
}
```

### 3.2 异常重新抛出

- 有时候希望把刚捕获的该异常对象，通过throw e的方式继续抛出，或者重新new一个新的异常进行抛出
- 单纯直接抛出： 原来的e的异常栈和调用方的e的异常栈信息一样
-  e.fillInStackTrace()重新填充了该异常，则就会丢失原来的e的异常栈， 新new一个异常并且抛出，同样的效果

```java
// 单纯直接抛出： e的栈信息不回发生任何改变
class EasyExcel {

    /**
     *  java.lang.ArithmeticException: / by zero
     * 	    at com.thinkinjava.EasyExcel.getInfo(Test01.java:24)
     * 	    at com.thinkinjava.EasyExcel.getInfoFrom(Test01.java:15)
     * 	    at com.thinkinjava.EasyExcel.main(Test01.java:10)
     * 	
     *   java.lang.ArithmeticException: / by zero
     *   	at com.thinkinjava.EasyExcel.getInfo(Test01.java:24)
     *   	at com.thinkinjava.EasyExcel.getInfoFrom(Test01.java:15)
     * 	    at com.thinkinjava.EasyExcel.main(Test01.java:10)
     * 	
     *   Exception in thread "main" java.lang.ArithmeticException: / by zero
     * 	    at com.thinkinjava.EasyExcel.getInfo(Test01.java:24)
     * 	    at com.thinkinjava.EasyExcel.getInfoFrom(Test01.java:15)
     * 	    at com.thinkinjava.EasyExcel.main(Test01.java:10)
     */
    public static void main(String[] args) {
        EasyExcel excel = new EasyExcel();
        excel.getInfoFrom();
    }

    public void getInfoFrom() {
        try {
            getInfo();
        } catch (Exception e) {
            e.printStackTrace();
            throw e;
        }
    }

    public void getInfo() {
        try {
            int i = 1 / 0;
        } catch (Exception e) {
            e.printStackTrace();
            throw e;
        }
    }
}
```



```java
// 异常 通过e.fillInStackTrace()，丢失原来的栈信息
class EasyExcel {
    /**
     * Exception in thread "main" java.lang.ArithmeticException: / by zero
     * 	at com.thinkinjava.EasyExcel.getInfoFrom(Test01.java:38)
     * 	at com.thinkinjava.EasyExcel.main(Test01.java:26)
     */
    public static void main(String[] args) {
        EasyExcel excel = new EasyExcel();
        excel.getInfoFrom();
    }

    /** 丢失了原来的 e， 得到一个新的e
     *  1。 得到一个Throwable对象，把当前调用栈信息填到原来的一场对象而建立的， fillInStackTrace也就成了新的异常的发生地了
     * java.lang.ArithmeticException: / by zero
     * 	at com.thinkinjava.EasyExcel.getInfoFrom(Test01.java:33)
     * 	at com.thinkinjava.EasyExcel.main(Test01.java:26)
     */
    public void getInfoFrom() {
        try {
            getInfo();
        } catch (Exception e) {
            Throwable throwable = e.fillInStackTrace();
            e.printStackTrace(System.out);
            throw e;
        }
    }

    /**
     * java.lang.ArithmeticException: / by zero
     * 	at com.thinkinjava.EasyExcel.getInfo(Test01.java:43)
     * 	at com.thinkinjava.EasyExcel.getInfoFrom(Test01.java:31)
     * 	at com.thinkinjava.EasyExcel.main(Test01.java:26)
     */
    public void getInfo() {
        try {
            int i = 1 / 0;
        } catch (Exception e) {
            e.printStackTrace();
            throw e;
        }
    }
}
```

### 3.3 异常链路

- 异常链: 捕获一个异常后并抛出另外一个异常，并把原始的异常信息保存下来
- Throwable子类在构造器中可以接受一个cause对象作为参数， 表示原始异常，这样就可以把原始异常传递给新的异常，就可以通过异常链追踪到异常最初发生的位置
- Java自带异常：只有Error, Exception, RuntimeException可以提供了这种构造器的方式进行异常链追踪，子类的都没有提供这种构造器
- Java自带异常： 如果不属于上面的几种，则可以用initCause的方式，在new新的异常的时候，传递原来异常链
- 自定义的异常：只需要自定义包含cause的构造器，就可以传递原来异常链

```java
class Computer {

    /**
     *   原来的异常链丢失
     *
     * Exception in thread "main" com.thinkinjava.ErickException: hehe
     * 	at com.thinkinjava.Computer.getInfoSecond(Test02.java:21)
     * 	at com.thinkinjava.Computer.main(Test02.java:14)
     * 
     */
    public static void main(String[] args) {
        Computer computer = new Computer();
        computer.getInfoSecond();
    }

    public void getInfoSecond() {
        try{
            getInfoFirst();
        }catch (Exception e){
            throw new ErickException("hehe");
        }
    }

    public void getInfoFirst() {
        int i = 1 / 0;
    }
}

class ErickException extends RuntimeException {
    public ErickException() {
    }

    public ErickException(String message) {
        super(message);
    }

    public ErickException(String message, Throwable t) {
        super(message, t);
    }
}
```

```java
class Computer {

    /**
     * 自定义的异常中： 包含了原来异常链
     *
     * Exception in thread "main" com.thinkinjava.ErickException: hehe
     * 	at com.thinkinjava.Computer.getInfoSecond(Test02.java:21)
     * 	at com.thinkinjava.Computer.main(Test02.java:14)
     * Caused by: java.lang.ArithmeticException: / by zero
     * 	at com.thinkinjava.Computer.getInfoFirst(Test02.java:26)
     * 	at com.thinkinjava.Computer.getInfoSecond(Test02.java:19)
     * 	... 1 more
     * 
     */
    public static void main(String[] args) {
        Computer computer = new Computer();
        computer.getInfoSecond();
    }

    public void getInfoSecond() {
        try{
            getInfoFirst();
        }catch (Exception e){
            throw new ErickException("hehe",e);
        }
    }

    public void getInfoFirst() {
        int i = 1 / 0;
    }
}

class ErickException extends RuntimeException {
    public ErickException() {
    }

    public ErickException(String message) {
        super(message);
    }

    public ErickException(String message, Throwable t) {
        super(message, t);
    }
}
```

```java
class Computer {

    public static void main(String[] args) {
        Computer computer = new Computer();
        computer.getInfoSecond();
    }

    public void getInfoSecond() {
        try {
            getInfoFirst();
        } catch (Exception e) {
            /**
             * Java中自带的异常体系， 如果不属于上面三种，可以通过initCause的方式传递异常链
             */
            NullPointerException nullPointerException = new NullPointerException();
            nullPointerException.initCause(e);
            throw nullPointerException;
        }
    }

    public void getInfoFirst() {
        List<String> list =null;
        System.out.println(list.size());
    }
}
```

## 4. 标准异常

- Throwable 异常是跟类， 分为  Error 和 Exception
- Error ：用来表示编译时和系统错误，一般不用关心
- Exception：可以被抛出的类型，分为RuntimeException（不受编译器检查的Exception） 和 CheckedException
- RuntimeException及其子类: 不受检查型异常，会被编译器自动捕获，并调用e.printStackTrace()打印出异常信息，然后退出当前程序，因此不用在代码中去显示的抛出
- 当然，也可以手动捕获上面的异常，这样的话，程序就不会异常退出

## 5. finally

- 一般用来进行清理工作
- finally中的内容一定会被执行，哪怕try模块中调用了return来进行方法返回

```java
package com.nike.exception;

import java.util.Random;

public class Demo04 {
    public static void main(String[] args) {
        getRandom();
    }

    public static void getRandom(){
        Random random = new Random();
        try{
            System.out.println(random.nextInt(10));
            return;
        }finally {
            System.out.println("finally块中的东西执行了");
        }
    }
}
```

# 二、缺陷

## 1.异常的丢失

- 在finally模块中，直接return

```java
class LostCase {
    /**
     * 直接return，使得主程序不会去管异常，这样RuntimeException就会完全丢失
     */
    public static void main(String[] args) {
        LostCase lostCase = new LostCase();
        try {
            lostCase.getName();
        } finally {
            return;
        }
    }

    public void getName() {
        throw new RuntimeException("haha");
    }
}
```

- 在同一个try catch finally中，一个异常还没处理完，又来了一个异常，那么原来的异常就会丢失

```java
class LostCase {

    public static void main(String[] args) {

        /**
         * 1. 在一个try catch模块中，getFirst的异常还没处理完毕， 在执行finally的时候
         * 又出现一个，这样就会丢失第一个异常
         */
        LostCase lostCase = new LostCase();
        try {
            lostCase.getFirst();
        } finally {
            lostCase.getSecond();
        }
        
    }

    public void getSecond() {
        throw new RuntimeException("second_exception");
    }

    public void getFirst() {
        throw new RuntimeException("first exception");
    }
}
```

## 2. 构造器

- 尽可能的不要在构造器中加入太多的东西，因为很容易引发乱七八糟的东西

## 3.最佳实践

- 不要大片大片的捕获异常，只要在你确定知道如何处理的情况下再去捕获异常；
- 把当前运行环境能做事情尽量做完，然后把相同的，不同的异常重新抛出到更高层
- 异常一般就是用来祈祷终止程序的

