***结构不佳的代码不能运行，除了编译期间的错误，运行时候的错误应该显示的进行处理***

------

# 一、基本异常

## 1. 基本步骤

- 使用new在堆上创建异常对象，然后当前的执行路径被终止，并且从当前环境中弹出对异常对象的引用
- 一场处理机制接管程序，并开始寻找一个恰当的地方来继续执行程序，即异常处理程序
- 异常处理程序是将程序从错误状态中恢复，使得程序要么换一种方式运行(抛出由调用方处理)，要么继续运行下去(不抛出，直接处理)

## 2. 异常参数

- 一般包含默认构造器和接受字符串作为参数的构造器，以便能把相关信息放入异常对象的构造器
- throw new NullPointerException("error message"): 将异常对象的引用抛出，类似于一个方法的返回值，用来结束当前方法
- 或者在方法声明中通过throws来进行异常抛出处理，两种情况都能起到同样的作用
-  Throwable 对象为所有异常的根类
- 一般通过try catch来进行多重异常捕获

```java
package com.nike.exception;

public class Demo01 {
    public static void main(String[] args) {
        BusinessException businessException = new BusinessException("贷款异常");
        System.out.println(businessException.getMessage());
    }
}

class BusinessException extends RuntimeException{

    String time;

    /**1. 默认无参构造器*/
    BusinessException(){
        super();
    }

    /**2. 带errorMessage的参构造器，显示调用父类构造器*/
    BusinessException(String message){
        super(message);
    }

    /**3. 更进一步自定义构造器*/
    BusinessException(String message, String time){
        super(message);
        this.time = time;
    }

    /**4. 可以对根类Throwable中的方法进行覆盖*/
    @Override
    public String getMessage(){
        return "接受消息";
    }
}
```

## 3. 异常说明

## 4. 异常捕获

### 4.1 常见方法

```java
package com.nike.exception;

public class Demo01 {
    public static void main(String[] args) {
        getInfo();

    }

    public static void getInfo() {
        try {
            int a = 1 / 0;
        } catch (Exception e) {
            /**1. 继承自基类Throwable的方法：
             *    e.getMessage()：             / by zero
             *    e.getLocalizedMessage()：    / by zero
             *    e.toString()：               java.lang.ArithmeticException: / by zero*/
            System.out.println("e.getMessage: " + e.getMessage());
            System.out.println("e.getLocalizedMessage：" + e.getLocalizedMessage());
            System.out.println("e.toString: " + e.toString());

            /**2. e.printStackTrace():  打印异常及异常调用栈轨迹
             *                         2.1 不管在什么catch中是什么代码顺序，都会放在最后面执行
             *                        
             *  java.lang.ArithmeticException: / by zero
             * 	at com.nike.exception.Demo01.getInfo(Demo01.java:12)
             * 	at com.nike.exception.Demo01.main(Demo01.java:5)
             *
             *  */
            System.out.println("hehe");
            e.printStackTrace();
            System.out.println("haha");

            /**3. 调用Object的方法打印类名  e.getClass().getSimpleName()：  ArithmeticException*/
            System.out.println(e.getClass().getSimpleName());


            /**4. 打印具体的栈轨迹：e.getStackTrace()
             *
             * com.nike.exception.Demo01.getInfo(Demo01.java:12)
             * com.nike.exception.Demo01.main(Demo01.java:5)
             * */
            StackTraceElement[] stackTrace = e.getStackTrace();
            for (StackTraceElement element : stackTrace) {
                System.out.println(element);
            }
        }

    }
}
```

### 4.2 异常抛出

- 有时候希望把刚捕获的该异常对象，通过throw e的方式继续抛出，或者重新new一个新的异常进行抛出
- 单纯直接抛出： 原来的e的异常栈和调用方的e的异常栈信息一样
-  e.fillInStackTrace()重新填充了该异常，则就会丢失原来的e的异常栈，重新new的来抛出效果类似

```java
package com.nike.exception;

public class Demo02 {
    public static void main(String[] args) {
        try {
            getCountDirectly();
        } catch (Exception e) {
            e.printStackTrace();
        }

        try {
            getCountFill();
        } catch (Exception e) {
            e.printStackTrace();
        }

        try {
            getCountThrowOther();
        } catch (Exception e) {
            e.printStackTrace();
        }

    }

    public static void getCountThrowOther() throws Exception {
        try {
            getCount();
        } catch (Exception e) {
            throw new Exception("捕获的重新仍一个");
        }
    }

    public static void getCountFill() throws Exception {
        try {
            getCount();
        } catch (Exception e) {
            /**重新处理之后，就会失去之前的异常的栈信息*/
            Throwable t = e.fillInStackTrace();
            throw (Exception) t;
        }
    }

    public static void getCountDirectly() throws Exception {
        try {
            getCount();
        } catch (Exception e) {
            throw e;
        }

    }

    public static void getCount() throws Exception {
        try {
            int i = 1 / 0;
        } catch (Exception e) {
            e.printStackTrace();
            throw e;
        }
    }
}
```



```javascript
java.lang.ArithmeticException: / by zero
	at com.nike.exception.Demo02.getCount(Demo02.java:55)
	at com.nike.exception.Demo02.getCountDirectly(Demo02.java:46)
	at com.nike.exception.Demo02.main(Demo02.java:6)
java.lang.ArithmeticException: / by zero
	at com.nike.exception.Demo02.getCount(Demo02.java:55)
	at com.nike.exception.Demo02.getCountDirectly(Demo02.java:46)
	at com.nike.exception.Demo02.main(Demo02.java:6)
java.lang.ArithmeticException: / by zero
	at com.nike.exception.Demo02.getCount(Demo02.java:55)
	at com.nike.exception.Demo02.getCountFill(Demo02.java:36)
	at com.nike.exception.Demo02.main(Demo02.java:13)
java.lang.ArithmeticException: / by zero
	at com.nike.exception.Demo02.getCountFill(Demo02.java:39)
	at com.nike.exception.Demo02.main(Demo02.java:13)
java.lang.ArithmeticException: / by zero
	at com.nike.exception.Demo02.getCount(Demo02.java:55)
	at com.nike.exception.Demo02.getCountThrowOther(Demo02.java:28)
	at com.nike.exception.Demo02.main(Demo02.java:19)
java.lang.Exception: 捕获的重新仍一个
	at com.nike.exception.Demo02.getCountThrowOther(Demo02.java:30)
	at com.nike.exception.Demo02.main(Demo02.java:19)
```

### 4.3 异常链路

- 如果捕获一个异常后并抛出另外一个异常，并且希望把原始的异常信息保存下来，这就是异常链
- Throwable的子类在构造器中可以接受一个cause对象作为参数，就是用来表示原始异常，这样就可以把原始异常传递给新的异常，使得可以通过异常链追踪到异常最初发生的位置
- 只有Error, Exception, RuntimeException可以使用这种构造器的方式进行异常链追踪

```java
package com.nike.exception;


/**这里以构造器传递作为一个模版*/
public class Demo03 {
    public static void main(String[] args) throws Exception {

        try {
            getCountThrow();
        } catch (Exception e) {
            e.printStackTrace();
        /*      java.lang.Exception: 新的异常
                    at com.nike.exception.Demo03.getCountThrow(Demo03.java:18)
                    at com.nike.exception.Demo03.main(Demo03.java:7)

         Caused by: java.lang.ArithmeticException: / by zero
                    at com.nike.exception.Demo03.getCount(Demo03.java:24)
                    at com.nike.exception.Demo03.getCountThrow(Demo03.java:15)
            ... 1 more*/
        }
    }

    public static void getCountThrow() throws Exception {
        try {
            getCount();
        } catch (Exception e) {
            /**1. 三类异常可以用这个带cause的参数，分别为Error，Exception， RuntimeException
               2. 只有抛出的新的异常属于上面三个，才可以用这种方式
               3. 三个指的就是三个异常，不包含其他的子类*/
            throw new Exception("新的异常", e);
        }
    }

    public static void getCount() throws Exception {
        try {
            int i = 1 / 0;
        } catch (Exception e) {
            throw e;
        }
    }
}
```

```java
package com.nike.exception;

/** 如果要抛出其他类型的异常*/
public class Demo03 {
    public static void main(String[] args) throws Exception {

        try {
            getCountThrow();
        } catch (Exception e) {
        /*
           java.lang.NoSuchFieldException: 新的异常
                    at com.nike.exception.Demo03.getCountThrow(Demo03.java:17)
                    at com.nike.exception.Demo03.main(Demo03.java:7)
          Caused by: java.lang.ArithmeticException: / by zero
                    at com.nike.exception.Demo03.getCount(Demo03.java:25)
                    at com.nike.exception.Demo03.getCountThrow(Demo03.java:15)
            ... 1 more*/
            e.printStackTrace();
        }
    }

    public static void getCountThrow() throws Exception {
        try {
            getCount();
        } catch (Exception e) {
            /**1. 新建一个要抛出的异常A
             * 2. 用A来init原来捕获的异常
             * 3. 将A抛出来*/
            NoSuchFieldException noSuchFieldException = new NoSuchFieldException("新的异常");
            noSuchFieldException.initCause(e);
            throw noSuchFieldException;
        }
    }

    public static void getCount() throws Exception {
        try {
            int i = 1 / 0;
        } catch (Exception e) {
            throw e;
        }
    }
}



```

## 5. 标准异常

- Throwable 异常分为  Error 和 Exception,其中Error  一般不需要关心
- 异常尽可能做到见名知意，很多异常的继承关系，也是为了方便用户知道这种异常大概是什么类型的异常
- RuntimeException及其子类: 不受检查型异常，会被编译器自动捕获，并调用e.printStackTrace()打印出异常信息，然后退出当前程序
- 当然，也可以手动捕获上面的异常，这样的话，程序就不会异常退出

## 6. finally

- finally中的内容一定会被执行，哪怕try模块中调用了return来进行方法返回

```java
package com.nike.exception;

import java.util.Random;

public class Demo04 {
    public static void main(String[] args) {
        getRandom();
    }

    public static void getRandom(){
        Random random = new Random();
        try{
            System.out.println(random.nextInt(10));
            return;
        }finally {
            System.out.println("finally块中的东西执行了");
        }
    }
}
```